<?xml version="1.0" ?>
<!--
  TurtleBot3 Burger Pro 主描述文件（可参数化）。

  说明：
  1) 本文件是“源文件”，建议优先修改这里。
  2) turtlebot3_burger_pro.urdf 可由 xacro 展开生成，适合运行时直接加载。
  3) 本体几何基本沿用 TB3 Burger，新增/调整了 camera_link 位姿用于你当前改装结构。
-->
<robot name="turtlebot3_burger"
  xmlns:xacro="http://ros.org/wiki/xacro">

  <!-- 保留与官方依赖对齐（当前未直接 include）。 -->
  <!-- <xacro:include filename="$(find turtlebot3_description)/urdf/common_properties.urdf"/> -->

  <!-- 多机器人扩展参数：为空时不加前缀。 -->
  <xacro:arg name="namespace" default=""/>
  <xacro:property name="namespace" value="$(arg namespace)"/>

  <!-- 可视化颜色定义（不影响物理，仅影响 RViz/Gazebo 外观）。 -->
  <material name="black"><color rgba="0.0 0.0 0.0 1.0"/></material>
  <material name="dark"><color rgba="0.3 0.3 0.3 1.0"/></material>
  <material name="light_black"><color rgba="0.4 0.4 0.4 1.0"/></material>
  <material name="blue"><color rgba="0.0 0.0 0.8 1.0"/></material>
  <material name="green"><color rgba="0.0 0.8 0.0 1.0"/></material>
  <material name="grey"><color rgba="0.5 0.5 0.5 1.0"/></material>
  <material name="orange"><color rgba="1.0 0.4235 0.0392 1.0"/></material>
  <material name="brown"><color rgba="0.8706 0.8118 0.7647 1.0"/></material>
  <material name="red"><color rgba="0.8 0.0 0.0 1.0"/></material>
  <material name="white"><color rgba="1.0 1.0 1.0 1.0"/></material>

  <!-- =========================
       1) 底盘与机体
       ========================= -->
  <link name="${namespace}base_footprint"/>

  <!-- base_footprint -> base_link：底盘离地高度 1cm -->
  <joint name="${namespace}base_joint" type="fixed">
    <parent link="${namespace}base_footprint"/>
    <child link="${namespace}base_link"/>
    <origin xyz="0.0 0.0 0.010" rpy="0 0 0"/>
  </joint>

  <link name="${namespace}base_link">
    <visual>
      <origin xyz="-0.032 0 0.0" rpy="0 0 0"/>
      <geometry>
        <mesh filename="package://turtlebot3_description/meshes/bases/burger_base.stl" scale="0.001 0.001 0.001"/>
      </geometry>
      <material name="light_black"/>
    </visual>

    <collision>
      <origin xyz="-0.032 0 0.070" rpy="0 0 0"/>
      <geometry>
        <box size="0.140 0.140 0.143"/>
      </geometry>
    </collision>

    <inertial>
      <origin xyz="0 0 0" rpy="0 0 0"/>
      <mass value="8.2573504e-01"/>
      <inertia ixx="2.2124416e-03" ixy="-1.2294101e-05" ixz="3.4938785e-05" iyy="2.1193702e-03" iyz="-5.0120904e-06" izz="2.0064271e-03" />
    </inertial>
  </link>

  <!-- =========================
       2) 差速轮
       ========================= -->
  <joint name="${namespace}wheel_left_joint" type="continuous">
    <parent link="${namespace}base_link"/>
    <child link="${namespace}wheel_left_link"/>
    <origin xyz="0.0 0.08 0.023" rpy="-1.57 0 0"/>
    <axis xyz="0 0 1"/>
    <dynamics damping="0.2" friction="0.2"/>
  </joint>

  <link name="${namespace}wheel_left_link">
    <visual>
      <origin xyz="0 0 0" rpy="1.57 0 0"/>
      <geometry>
        <mesh filename="package://turtlebot3_description/meshes/wheels/left_tire.stl" scale="0.001 0.001 0.001"/>
      </geometry>
      <material name="dark"/>
    </visual>

    <collision>
      <origin xyz="0 0 0" rpy="0 0 0"/>
      <geometry>
        <cylinder length="0.018" radius="0.033"/>
      </geometry>
    </collision>

    <inertial>
      <origin xyz="0 0 0" />
      <mass value="2.8498940e-02" />
      <inertia ixx="1.1175580e-05" ixy="-4.2369783e-11" ixz="-5.9381719e-09" iyy="1.1192413e-05" iyz="-1.4400107e-11" izz="2.0712558e-05" />
    </inertial>
  </link>

  <joint name="${namespace}wheel_right_joint" type="continuous">
    <parent link="${namespace}base_link"/>
    <child link="${namespace}wheel_right_link"/>
    <origin xyz="0.0 -0.080 0.023" rpy="-1.57 0 0"/>
    <axis xyz="0 0 1"/>
    <dynamics damping="0.2" friction="0.2"/>
  </joint>

  <link name="${namespace}wheel_right_link">
    <visual>
      <origin xyz="0 0 0" rpy="1.57 0 0"/>
      <geometry>
        <mesh filename="package://turtlebot3_description/meshes/wheels/right_tire.stl" scale="0.001 0.001 0.001"/>
      </geometry>
      <material name="dark"/>
    </visual>

    <collision>
      <origin xyz="0 0 0" rpy="0 0 0"/>
      <geometry>
        <cylinder length="0.018" radius="0.033"/>
      </geometry>
    </collision>

    <inertial>
      <origin xyz="0 0 0" />
      <mass value="2.8498940e-02" />
      <inertia ixx="1.1175580e-05" ixy="-4.2369783e-11" ixz="-5.9381719e-09" iyy="1.1192413e-05" iyz="-1.4400107e-11" izz="2.0712558e-05" />
    </inertial>
  </link>

  <!-- 后万向轮（被动） -->
  <joint name="${namespace}caster_back_joint" type="fixed">
    <parent link="${namespace}base_link"/>
    <child link="${namespace}caster_back_link"/>
    <origin xyz="-0.081 0 -0.004" rpy="-1.57 0 0"/>
  </joint>

  <link name="${namespace}caster_back_link">
    <collision>
      <origin xyz="0 0.001 0" rpy="0 0 0"/>
      <geometry>
        <box size="0.030 0.009 0.020"/>
      </geometry>
    </collision>

    <inertial>
      <origin xyz="0 0 0" />
      <mass value="0.005" />
      <inertia ixx="0.001" ixy="0.0" ixz="0.0" iyy="0.001" iyz="0.0" izz="0.001" />
    </inertial>
  </link>

  <!-- =========================
       3) 传感器坐标系（TF）
       ========================= -->
  <joint name="${namespace}imu_joint" type="fixed">
    <parent link="${namespace}base_link"/>
    <child link="${namespace}imu_link"/>
    <origin xyz="-0.032 0 0.068" rpy="0 0 0"/>
  </joint>
  <link name="${namespace}imu_link"/>

  <joint name="${namespace}scan_joint" type="fixed">
    <parent link="${namespace}base_link"/>
    <child link="${namespace}base_scan"/>
    <origin xyz="-0.032 0 0.172" rpy="0 0 0"/>
  </joint>

  <link name="${namespace}base_scan">
    <visual>
      <origin xyz="0 0 0.0" rpy="0 0 0"/>
      <geometry>
        <mesh filename="package://turtlebot3_description/meshes/sensors/lds.stl" scale="0.001 0.001 0.001"/>
      </geometry>
      <material name="dark"/>
    </visual>

    <collision>
      <origin xyz="0.015 0 -0.0065" rpy="0 0 0"/>
      <geometry>
        <cylinder length="0.0315" radius="0.055"/>
      </geometry>
    </collision>

    <inertial>
      <mass value="0.114" />
      <origin xyz="0 0 0" />
      <inertia ixx="0.001" ixy="0.0" ixz="0.0" iyy="0.001" iyz="0.0" izz="0.001" />
    </inertial>
  </link>

  <!-- D435i 近似安装位姿：前上方 -->
  <joint name="${namespace}camera_joint" type="fixed">
    <parent link="${namespace}base_link"/>
    <child link="${namespace}camera_link"/>
    <origin xyz="0.012 0 0.155" rpy="0 0 0"/>
  </joint>

  <link name="${namespace}camera_link">
    <visual>
      <origin xyz="0 0 0" rpy="0 0 0"/>
      <geometry>
        <box size="0.09 0.025 0.025"/>
      </geometry>
      <material name="blue"/>
    </visual>

    <collision>
      <origin xyz="0 0 0" rpy="0 0 0"/>
      <geometry>
        <box size="0.09 0.025 0.025"/>
      </geometry>
    </collision>

    <inertial>
      <mass value="0.072"/>
      <origin xyz="0 0 0"/>
      <inertia ixx="1e-4" ixy="0.0" ixz="0.0" iyy="1e-4" iyz="0.0" izz="1e-4"/>
    </inertial>
  </link>

</robot>
